Successfully Written Error Logs
Successfully Written Logs
<Response [200]>
Successfully Written Error Logs
Successfully Written Logs
<Response [200]>
Successfully Written Error Logs
Successfully Written Logs
<Response [200]>
Successfully Written Error Logs
Successfully Written Logs
<Response [200]>
Successfully Written Error Logs
Successfully Written Logs
<Response [200]>
Successfully Written Error Logs
Successfully Written Logs
<Response [200]>
Traceback (most recent call last):
  File "/home/analytics-admin/.local/lib/python3.8/site-packages/pandas/core/indexes/base.py", line 3080, in get_loc
    return self._engine.get_loc(casted_key)
  File "pandas/_libs/index.pyx", line 70, in pandas._libs.index.IndexEngine.get_loc
  File "pandas/_libs/index.pyx", line 101, in pandas._libs.index.IndexEngine.get_loc
  File "pandas/_libs/hashtable_class_helper.pxi", line 4554, in pandas._libs.hashtable.PyObjectHashTable.get_item
  File "pandas/_libs/hashtable_class_helper.pxi", line 4562, in pandas._libs.hashtable.PyObjectHashTable.get_item
KeyError: 'date'

The above exception was the direct cause of the following exception:

Traceback (most recent call last):
  File "/home/analytics-admin/script.py", line 12, in <module>
    df_new['date'] = df_new['date'].str.replace(',','')
  File "/home/analytics-admin/.local/lib/python3.8/site-packages/pandas/core/frame.py", line 3024, in __getitem__
    indexer = self.columns.get_loc(key)
  File "/home/analytics-admin/.local/lib/python3.8/site-packages/pandas/core/indexes/base.py", line 3082, in get_loc
    raise KeyError(key) from err
KeyError: 'date'
Traceback (most recent call last):
  File "/home/analytics-admin/.local/lib/python3.8/site-packages/pandas/core/indexes/base.py", line 3080, in get_loc
    return self._engine.get_loc(casted_key)
  File "pandas/_libs/index.pyx", line 70, in pandas._libs.index.IndexEngine.get_loc
  File "pandas/_libs/index.pyx", line 101, in pandas._libs.index.IndexEngine.get_loc
  File "pandas/_libs/hashtable_class_helper.pxi", line 4554, in pandas._libs.hashtable.PyObjectHashTable.get_item
  File "pandas/_libs/hashtable_class_helper.pxi", line 4562, in pandas._libs.hashtable.PyObjectHashTable.get_item
KeyError: 'date'

The above exception was the direct cause of the following exception:

Traceback (most recent call last):
  File "/home/analytics-admin/script.py", line 12, in <module>
    df_new['date'] = df_new['date'].str.replace(',','')
  File "/home/analytics-admin/.local/lib/python3.8/site-packages/pandas/core/frame.py", line 3024, in __getitem__
    indexer = self.columns.get_loc(key)
  File "/home/analytics-admin/.local/lib/python3.8/site-packages/pandas/core/indexes/base.py", line 3082, in get_loc
    raise KeyError(key) from err
KeyError: 'date'
Traceback (most recent call last):
  File "/home/analytics-admin/.local/lib/python3.8/site-packages/pandas/core/indexes/base.py", line 3080, in get_loc
    return self._engine.get_loc(casted_key)
  File "pandas/_libs/index.pyx", line 70, in pandas._libs.index.IndexEngine.get_loc
  File "pandas/_libs/index.pyx", line 101, in pandas._libs.index.IndexEngine.get_loc
  File "pandas/_libs/hashtable_class_helper.pxi", line 4554, in pandas._libs.hashtable.PyObjectHashTable.get_item
  File "pandas/_libs/hashtable_class_helper.pxi", line 4562, in pandas._libs.hashtable.PyObjectHashTable.get_item
KeyError: 'date'

The above exception was the direct cause of the following exception:

Traceback (most recent call last):
  File "/home/analytics-admin/script.py", line 12, in <module>
    df_new['date'] = df_new['date'].str.replace(',','')
  File "/home/analytics-admin/.local/lib/python3.8/site-packages/pandas/core/frame.py", line 3024, in __getitem__
    indexer = self.columns.get_loc(key)
  File "/home/analytics-admin/.local/lib/python3.8/site-packages/pandas/core/indexes/base.py", line 3082, in get_loc
    raise KeyError(key) from err
KeyError: 'date'
Successfully Written Error Logs
Successfully Written Logs
<Response [200]>
Successfully Written Error Logs
Successfully Written Logs
<Response [200]>
Successfully Written Error Logs
Successfully Written Logs
<Response [200]>
Successfully Written Error Logs
Successfully Written Logs
<Response [200]>
Traceback (most recent call last):
  File "/home/analytics-admin/script.py", line 15, in <module>
    df_new['lat'] = df_new['lat'].astype(float)
  File "/home/analytics-admin/.local/lib/python3.8/site-packages/pandas/core/generic.py", line 5877, in astype
    new_data = self._mgr.astype(dtype=dtype, copy=copy, errors=errors)
  File "/home/analytics-admin/.local/lib/python3.8/site-packages/pandas/core/internals/managers.py", line 631, in astype
    return self.apply("astype", dtype=dtype, copy=copy, errors=errors)
  File "/home/analytics-admin/.local/lib/python3.8/site-packages/pandas/core/internals/managers.py", line 427, in apply
    applied = getattr(b, f)(**kwargs)
  File "/home/analytics-admin/.local/lib/python3.8/site-packages/pandas/core/internals/blocks.py", line 673, in astype
    values = astype_nansafe(vals1d, dtype, copy=True)
  File "/home/analytics-admin/.local/lib/python3.8/site-packages/pandas/core/dtypes/cast.py", line 1097, in astype_nansafe
    return arr.astype(dtype, copy=True)
ValueError: could not convert string to float: 'html'
Traceback (most recent call last):
  File "/home/analytics-admin/script.py", line 15, in <module>
    df_new['lat'] = df_new['lat'].astype(float)
  File "/home/analytics-admin/.local/lib/python3.8/site-packages/pandas/core/generic.py", line 5877, in astype
    new_data = self._mgr.astype(dtype=dtype, copy=copy, errors=errors)
  File "/home/analytics-admin/.local/lib/python3.8/site-packages/pandas/core/internals/managers.py", line 631, in astype
    return self.apply("astype", dtype=dtype, copy=copy, errors=errors)
  File "/home/analytics-admin/.local/lib/python3.8/site-packages/pandas/core/internals/managers.py", line 427, in apply
    applied = getattr(b, f)(**kwargs)
  File "/home/analytics-admin/.local/lib/python3.8/site-packages/pandas/core/internals/blocks.py", line 673, in astype
    values = astype_nansafe(vals1d, dtype, copy=True)
  File "/home/analytics-admin/.local/lib/python3.8/site-packages/pandas/core/dtypes/cast.py", line 1097, in astype_nansafe
    return arr.astype(dtype, copy=True)
ValueError: could not convert string to float: 'html'
Traceback (most recent call last):
  File "/home/analytics-admin/script.py", line 15, in <module>
    df_new['lat'] = df_new['lat'].astype(float)
  File "/home/analytics-admin/.local/lib/python3.8/site-packages/pandas/core/generic.py", line 5877, in astype
    new_data = self._mgr.astype(dtype=dtype, copy=copy, errors=errors)
  File "/home/analytics-admin/.local/lib/python3.8/site-packages/pandas/core/internals/managers.py", line 631, in astype
    return self.apply("astype", dtype=dtype, copy=copy, errors=errors)
  File "/home/analytics-admin/.local/lib/python3.8/site-packages/pandas/core/internals/managers.py", line 427, in apply
    applied = getattr(b, f)(**kwargs)
  File "/home/analytics-admin/.local/lib/python3.8/site-packages/pandas/core/internals/blocks.py", line 673, in astype
    values = astype_nansafe(vals1d, dtype, copy=True)
  File "/home/analytics-admin/.local/lib/python3.8/site-packages/pandas/core/dtypes/cast.py", line 1097, in astype_nansafe
    return arr.astype(dtype, copy=True)
ValueError: could not convert string to float: 'html'
Killed
Killed
Killed
Killed
Killed
Killed
Traceback (most recent call last):
  File "/usr/lib/python3/dist-packages/urllib3/connectionpool.py", line 665, in urlopen
    httplib_response = self._make_request(
  File "/usr/lib/python3/dist-packages/urllib3/connectionpool.py", line 421, in _make_request
    six.raise_from(e, None)
  File "<string>", line 3, in raise_from
  File "/usr/lib/python3/dist-packages/urllib3/connectionpool.py", line 416, in _make_request
    httplib_response = conn.getresponse()
  File "/usr/lib/python3.8/http/client.py", line 1348, in getresponse
    response.begin()
  File "/usr/lib/python3.8/http/client.py", line 316, in begin
    version, status, reason = self._read_status()
  File "/usr/lib/python3.8/http/client.py", line 285, in _read_status
    raise RemoteDisconnected("Remote end closed connection without"
http.client.RemoteDisconnected: Remote end closed connection without response

During handling of the above exception, another exception occurred:

Traceback (most recent call last):
  File "/home/analytics-admin/.local/lib/python3.8/site-packages/requests/adapters.py", line 439, in send
    resp = conn.urlopen(
  File "/usr/lib/python3/dist-packages/urllib3/connectionpool.py", line 719, in urlopen
    retries = retries.increment(
  File "/usr/lib/python3/dist-packages/urllib3/util/retry.py", line 400, in increment
    raise six.reraise(type(error), error, _stacktrace)
  File "/usr/lib/python3/dist-packages/six.py", line 702, in reraise
    raise value.with_traceback(tb)
  File "/usr/lib/python3/dist-packages/urllib3/connectionpool.py", line 665, in urlopen
    httplib_response = self._make_request(
  File "/usr/lib/python3/dist-packages/urllib3/connectionpool.py", line 421, in _make_request
    six.raise_from(e, None)
  File "<string>", line 3, in raise_from
  File "/usr/lib/python3/dist-packages/urllib3/connectionpool.py", line 416, in _make_request
    httplib_response = conn.getresponse()
  File "/usr/lib/python3.8/http/client.py", line 1348, in getresponse
    response.begin()
  File "/usr/lib/python3.8/http/client.py", line 316, in begin
    version, status, reason = self._read_status()
  File "/usr/lib/python3.8/http/client.py", line 285, in _read_status
    raise RemoteDisconnected("Remote end closed connection without"
urllib3.exceptions.ProtocolError: ('Connection aborted.', RemoteDisconnected('Remote end closed connection without response'))

During handling of the above exception, another exception occurred:

Traceback (most recent call last):
  File "/home/analytics-admin/script.py", line 8, in <module>
    responses = requests.get("http://20.123.74.246:5000/getdata")
  File "/home/analytics-admin/.local/lib/python3.8/site-packages/requests/api.py", line 76, in get
    return request('get', url, params=params, **kwargs)
  File "/home/analytics-admin/.local/lib/python3.8/site-packages/requests/api.py", line 61, in request
    return session.request(method=method, url=url, **kwargs)
  File "/home/analytics-admin/.local/lib/python3.8/site-packages/requests/sessions.py", line 542, in request
    resp = self.send(prep, **send_kwargs)
  File "/home/analytics-admin/.local/lib/python3.8/site-packages/requests/sessions.py", line 655, in send
    r = adapter.send(request, **kwargs)
  File "/home/analytics-admin/.local/lib/python3.8/site-packages/requests/adapters.py", line 498, in send
    raise ConnectionError(err, request=request)
requests.exceptions.ConnectionError: ('Connection aborted.', RemoteDisconnected('Remote end closed connection without response'))
Traceback (most recent call last):
  File "/usr/lib/python3/dist-packages/urllib3/connection.py", line 159, in _new_conn
    conn = connection.create_connection(
  File "/usr/lib/python3/dist-packages/urllib3/util/connection.py", line 84, in create_connection
    raise err
  File "/usr/lib/python3/dist-packages/urllib3/util/connection.py", line 74, in create_connection
    sock.connect(sa)
ConnectionRefusedError: [Errno 111] Connection refused

During handling of the above exception, another exception occurred:

Traceback (most recent call last):
  File "/usr/lib/python3/dist-packages/urllib3/connectionpool.py", line 665, in urlopen
    httplib_response = self._make_request(
  File "/usr/lib/python3/dist-packages/urllib3/connectionpool.py", line 387, in _make_request
    conn.request(method, url, **httplib_request_kw)
  File "/usr/lib/python3.8/http/client.py", line 1256, in request
    self._send_request(method, url, body, headers, encode_chunked)
  File "/usr/lib/python3.8/http/client.py", line 1302, in _send_request
    self.endheaders(body, encode_chunked=encode_chunked)
  File "/usr/lib/python3.8/http/client.py", line 1251, in endheaders
    self._send_output(message_body, encode_chunked=encode_chunked)
  File "/usr/lib/python3.8/http/client.py", line 1011, in _send_output
    self.send(msg)
  File "/usr/lib/python3.8/http/client.py", line 951, in send
    self.connect()
  File "/usr/lib/python3/dist-packages/urllib3/connection.py", line 187, in connect
    conn = self._new_conn()
  File "/usr/lib/python3/dist-packages/urllib3/connection.py", line 171, in _new_conn
    raise NewConnectionError(
urllib3.exceptions.NewConnectionError: <urllib3.connection.HTTPConnection object at 0x7f0cd291cdf0>: Failed to establish a new connection: [Errno 111] Connection refused

During handling of the above exception, another exception occurred:

Traceback (most recent call last):
  File "/home/analytics-admin/.local/lib/python3.8/site-packages/requests/adapters.py", line 439, in send
    resp = conn.urlopen(
  File "/usr/lib/python3/dist-packages/urllib3/connectionpool.py", line 719, in urlopen
    retries = retries.increment(
  File "/usr/lib/python3/dist-packages/urllib3/util/retry.py", line 436, in increment
    raise MaxRetryError(_pool, url, error or ResponseError(cause))
urllib3.exceptions.MaxRetryError: HTTPConnectionPool(host='20.123.74.246', port=5000): Max retries exceeded with url: /getdata (Caused by NewConnectionError('<urllib3.connection.HTTPConnection object at 0x7f0cd291cdf0>: Failed to establish a new connection: [Errno 111] Connection refused'))

During handling of the above exception, another exception occurred:

Traceback (most recent call last):
  File "/home/analytics-admin/script.py", line 8, in <module>
    responses = requests.get("http://20.123.74.246:5000/getdata")
  File "/home/analytics-admin/.local/lib/python3.8/site-packages/requests/api.py", line 76, in get
    return request('get', url, params=params, **kwargs)
  File "/home/analytics-admin/.local/lib/python3.8/site-packages/requests/api.py", line 61, in request
    return session.request(method=method, url=url, **kwargs)
  File "/home/analytics-admin/.local/lib/python3.8/site-packages/requests/sessions.py", line 542, in request
    resp = self.send(prep, **send_kwargs)
  File "/home/analytics-admin/.local/lib/python3.8/site-packages/requests/sessions.py", line 655, in send
    r = adapter.send(request, **kwargs)
  File "/home/analytics-admin/.local/lib/python3.8/site-packages/requests/adapters.py", line 516, in send
    raise ConnectionError(e, request=request)
requests.exceptions.ConnectionError: HTTPConnectionPool(host='20.123.74.246', port=5000): Max retries exceeded with url: /getdata (Caused by NewConnectionError('<urllib3.connection.HTTPConnection object at 0x7f0cd291cdf0>: Failed to establish a new connection: [Errno 111] Connection refused'))
